Workbook

Sheet Presentation
E5: 45657 | F5: 46022 | G5: 46387 | H5: 46752 | I5: 47118 | J5: 47483 | K5: 47848 | L5: 48213 | O5: 45657 | P5: 46022 | Q5: 46387 | R5: 46752 | S5: 47118 | T5: 47483 | U5: 47848 | V5: 48213 | Z5: =P5 -> 46022 | AA5: =Q5 -> 46387 | AB5: =R5 -> 46752 | AC5: =S5 -> 47118 | AD5: =T5 -> 47483 | AE5: =U5 -> 47848 | AF5: =V5 -> 48213
D6: ='Valuation (Base)'!D5 -> Revenue | E6: ='Valuation (Base)'!F5 -> 3820845.7 | F6: ='Valuation (Base)'!G5 -> 3800977.3 | G6: ='Valuation (Base)'!H5 -> 3978863.1 | H6: ='Valuation (Base)'!I5 -> 4240672.3 | I6: ='Valuation (Base)'!J5 -> 4373829.4 | J6: ='Valuation (Base)'!K5 -> 4592520.9 | K6: ='Valuation (Base)'!L5 -> 4765934.4 | L6: ='Valuation (Base)'!M5 -> 4986845 | N6: Revenue | O6: ='Valuation (Downside)'!F5 -> 3820845.7 | P6: ='Valuation (Downside)'!G5 -> 3629803.5 | Q6: ='Valuation (Downside)'!H5 -> 3520909.4 | R6: ='Valuation (Downside)'!I5 -> 3520909.4 | S6: ='Valuation (Downside)'!J5 -> 3591327.5 | T6: ='Valuation (Downside)'!K5 -> 3699067.4 | U6: ='Valuation (Downside)'!L5 -> 3838744.2 | V6: ='Valuation (Downside)'!M5 -> 4016677.6 | X6: =_xlfn.CONCAT("Δ ",N6) -> Δ Revenue | Z6: =P6-F6 -> -171173.89 | AA6: =Q6-G6 -> -457953.73 | AB6: =R6-H6 -> -719762.92 | AC6: =S6-I6 -> -782501.85 | AD6: =T6-J6 -> -893453.49 | AE6: =U6-K6 -> -927190.29 | AF6: =V6-L6 -> -970167.42
D7: ='Valuation (Base)'!D72 -> EBITDA | E7: ='Valuation (Base)'!F72 -> 478336.62 | F7: ='Valuation (Base)'!G72 -> 484191.38 | G7: ='Valuation (Base)'!H72 -> 506656.92 | H7: ='Valuation (Base)'!I72 -> 555267.69 | I7: ='Valuation (Base)'!J72 -> 564646.36 | J7: ='Valuation (Base)'!K72 -> 584684.72 | K7: ='Valuation (Base)'!L72 -> 612013.34 | L7: ='Valuation (Base)'!M72 -> 641406.79 | N7: EBITDA | O7: ='Valuation (Downside)'!F66 -> 478336.62 | P7: ='Valuation (Downside)'!G66 -> 371641.13 | Q7: ='Valuation (Downside)'!H66 -> 377924.23 | R7: ='Valuation (Downside)'!I66 -> 415251.12 | S7: ='Valuation (Downside)'!J66 -> 434897.44 | T7: ='Valuation (Downside)'!K66 -> 470937.04 | U7: ='Valuation (Downside)'!L66 -> 492949 | V7: ='Valuation (Downside)'!M66 -> 516624.1 | X7: =_xlfn.CONCAT("Δ ",N7) -> Δ EBITDA | Z7: =P7-F7 -> -112550.25 | AA7: =Q7-G7 -> -128732.69 | AB7: =R7-H7 -> -140016.57 | AC7: =S7-I7 -> -129748.92 | AD7: =T7-J7 -> -113747.68 | AE7: =U7-K7 -> -119064.34 | AF7: =V7-L7 -> -124782.7
D8: ='Valuation (Base)'!D9 -> EBIT | E8: ='Valuation (Base)'!F9 -> 396112.25 | F8: ='Valuation (Base)'!G9 -> 406509.1 | G8: ='Valuation (Base)'!H9 -> 426294.94 | H8: ='Valuation (Base)'!I9 -> 470491.83 | I8: ='Valuation (Base)'!J9 -> 476396.03 | J8: ='Valuation (Base)'!K9 -> 490700.95 | K8: ='Valuation (Base)'!L9 -> 515486.74 | L8: ='Valuation (Base)'!M9 -> 540589.51 | N8: EBIT | O8: ='Valuation (Downside)'!F9 -> 396112.25 | P8: ='Valuation (Downside)'!G9 -> 297457.21 | Q8: ='Valuation (Downside)'!H9 -> 306811.64 | R8: ='Valuation (Downside)'!I9 -> 344864.14 | S8: ='Valuation (Downside)'!J9 -> 362435.57 | T8: ='Valuation (Downside)'!K9 -> 395237.37 | U8: ='Valuation (Downside)'!L9 -> 415201.2 | V8: ='Valuation (Downside)'!M9 -> 435420.34 | X8: =_xlfn.CONCAT("Δ ",N8) -> Δ EBIT | Z8: =P8-F8 -> -109051.89 | AA8: =Q8-G8 -> -119483.3 | AB8: =R8-H8 -> -125627.69 | AC8: =S8-I8 -> -113960.46 | AD8: =T8-J8 -> -95463.578 | AE8: =U8-K8 -> -100285.54 | AF8: =V8-L8 -> -105169.16
D9: ='Valuation (Base)'!D13 -> Net Income | E9: ='Valuation (Base)'!F13 -> 266918.14 | F9: ='Valuation (Base)'!G13 -> 277602.98 | G9: ='Valuation (Base)'!H13 -> 291954.03 | H9: ='Valuation (Base)'!I13 -> 323881.59 | I9: ='Valuation (Base)'!J13 -> 327513.49 | J9: ='Valuation (Base)'!K13 -> 337670.52 | K9: ='Valuation (Base)'!L13 -> 356290.05 | L9: ='Valuation (Base)'!M13 -> 374377.5 | N9: Net Income | O9: ='Valuation (Downside)'!F13 -> 266918.14 | P9: ='Valuation (Downside)'!G13 -> 195976.97 | Q9: ='Valuation (Downside)'!H13 -> 203601.86 | R9: ='Valuation (Downside)'!I13 -> 231974.86 | S9: ='Valuation (Downside)'!J13 -> 244651.28 | T9: ='Valuation (Downside)'!K13 -> 269173.34 | U9: ='Valuation (Downside)'!L13 -> 284155.85 | V9: ='Valuation (Downside)'!M13 -> 298777.87 | X9: =_xlfn.CONCAT("Δ ",N9) -> Δ Net Income | Z9: =P9-F9 -> -81626.008 | AA9: =Q9-G9 -> -88352.166 | AB9: =R9-H9 -> -91906.733 | AC9: =S9-I9 -> -82862.21 | AD9: =T9-J9 -> -68497.179 | AE9: =U9-K9 -> -72134.2 | AF9: =V9-L9 -> -75599.628
D10: Free Cash Flow | E10: ='Valuation (Base)'!F17 -> 257155.98 | F10: ='Valuation (Base)'!G17 -> 329315.33 | G10: ='Valuation (Base)'!H17 -> 275755.63 | H10: ='Valuation (Base)'!I17 -> 281751.36 | I10: ='Valuation (Base)'!J17 -> 320125.97 | J10: ='Valuation (Base)'!K17 -> 306573.89 | K10: ='Valuation (Base)'!L17 -> 342268.46 | L10: ='Valuation (Base)'!M17 -> 350798.57 | N10: Free Cash Flow | O10: ='Valuation (Downside)'!F17 -> 257155.98 | P10: ='Valuation (Downside)'!G17 -> 186827.5 | Q10: ='Valuation (Downside)'!H17 -> 264325.8 | R10: ='Valuation (Downside)'!I17 -> 278154.25 | S10: ='Valuation (Downside)'!J17 -> 251876.13 | T10: ='Valuation (Downside)'!K17 -> 270291.95 | U10: ='Valuation (Downside)'!L17 -> 271274.86 | V10: ='Valuation (Downside)'!M17 -> 279078.56 | X10: =_xlfn.CONCAT("Δ ",N10) -> Δ Free Cash Flow | Z10: =P10-F10 -> -142487.83 | AA10: =Q10-G10 -> -11429.838 | AB10: =R10-H10 -> -3597.1139 | AC10: =S10-I10 -> -68249.838 | AD10: =T10-J10 -> -36281.94 | AE10: =U10-K10 -> -70993.599 | AF10: =V10-L10 -> -71720.001
D11: Equity Value | E11: ='Valuation (Base)'!M32 -> 4045942.7 | N11: Equity Value | O11: ='Valuation (Downside)'!M32 -> 3198602.3
D12: ='Valuation (Base)'!D41 -> Market Capitalization | E12: ='Valuation (Base)'!F41 -> 4129223.7 | N12: Market Capitalization | O12: ='Valuation (Downside)'!F41 -> 3203017.7
E14: 45657 | F14: 46022 | G14: 46387 | H14: 46752 | I14: 47118 | J14: 47483 | K14: 47848 | L14: 48213 | O14: 45657 | P14: 46022 | Q14: 46387 | R14: 46752 | S14: 47118 | T14: 47483 | U14: 47848 | V14: 48213 | Z14: =Z5 -> 46022 | AA14: =AA5 -> 46387 | AB14: =AB5 -> 46752 | AC14: =AC5 -> 47118 | AD14: =AD5 -> 47483 | AE14: =AE5 -> 47848 | AF14: =AF5 -> 48213
D15: ='Valuation (Base)'!D60 -> Debt-to-EBITDA | E15: ='Valuation (Base)'!F60 -> 1.1006361 | F15: ='Valuation (Base)'!G60 -> 1.0608635 | G15: ='Valuation (Base)'!H60 -> 1.0425161 | H15: ='Valuation (Base)'!I60 -> 0.97422874 | I15: ='Valuation (Base)'!J60 -> 0.98333907 | J15: ='Valuation (Base)'!K60 -> 0.9690077 | K15: ='Valuation (Base)'!L60 -> 0.93750013 | L15: ='Valuation (Base)'!M60 -> 0.91895858 | N15: =D15 -> Debt-to-EBITDA | O15: ='Valuation (Downside)'!F60 -> 1.1013854 | P15: ='Valuation (Downside)'!G60 -> 1.4102273 | Q15: ='Valuation (Downside)'!H60 -> 1.3807549 | R15: ='Valuation (Downside)'!I60 -> 1.2231208 | S15: ='Valuation (Downside)'!J60 -> 1.1733228 | T15: ='Valuation (Downside)'!K60 -> 1.0800245 | U15: ='Valuation (Downside)'!L60 -> 1.0594675 | V15: ='Valuation (Downside)'!M60 -> 1.0192473 | X15: Revenue | Z15: ='3-Statement (Downside)'!L10 -> -0.05 | AA15: ='3-Statement (Downside)'!M10 -> -0.03 | AB15: ='3-Statement (Downside)'!N10 -> 0 | AC15: ='3-Statement (Downside)'!O10 -> 0.02 | AD15: ='3-Statement (Downside)'!P10 -> 0.03 | AE15: ='3-Statement (Downside)'!Q10 -> 0.03776 | AF15: ='3-Statement (Downside)'!R10 -> 0.046352
D16: ='Valuation (Base)'!D64 -> Interest Coverage | E16: ='Valuation (Base)'!F64 -> 21.080314 | F16: ='Valuation (Base)'!G64 -> 21.681084 | G16: ='Valuation (Base)'!H64 -> 22.867734 | H16: ='Valuation (Base)'!I64 -> 25.571601 | I16: ='Valuation (Base)'!J64 -> 26.223442 | J16: ='Valuation (Base)'!K64 -> 27.369635 | K16: ='Valuation (Base)'!L64 -> 29.112104 | L16: ='Valuation (Base)'!M64 -> 30.877567 | N16: =D16 -> Interest Coverage | O16: ='Valuation (Downside)'!F64 -> 21.080314 | P16: ='Valuation (Downside)'!G64 -> 15.866339 | Q16: ='Valuation (Downside)'!H64 -> 16.504497 | R16: ='Valuation (Downside)'!I64 -> 18.71121 | S16: ='Valuation (Downside)'!J64 -> 19.770568 | T16: ='Valuation (Downside)'!K64 -> 21.771987 | U16: ='Valuation (Downside)'!L64 -> 23.071017 | V16: ='Valuation (Downside)'!M64 -> 24.509994 | X16: Δ COGS % Revenue | Z16: ='3-Statement (Downside)'!L12 -> 0.01 | AA16: ='3-Statement (Downside)'!M12 -> 0.008 | AB16: ='3-Statement (Downside)'!N12 -> 0.005 | AC16: ='3-Statement (Downside)'!O12 -> 0.003 | AD16: ='3-Statement (Downside)'!P12 -> 0 | AE16: ='3-Statement (Downside)'!Q12 -> 0 | AF16: ='3-Statement (Downside)'!R12 -> 0
D17: ='Valuation (Base)'!D70 -> Debt Service Coverage Ratio | E17: ='Valuation (Base)'!F70 -> 22.8102 | F17: ='Valuation (Base)'!G70 -> 23.158661 | G17: ='Valuation (Base)'!H70 -> 24.383723 | H17: ='Valuation (Base)'!I70 -> 27.066998 | I17: ='Valuation (Base)'!J70 -> 27.868054 | J17: ='Valuation (Base)'!K70 -> 29.230517 | K17: ='Valuation (Base)'!L70 -> 30.971858 | L17: ='Valuation (Base)'!M70 -> 32.824424 | N17: =D17 -> Debt Service Coverage Ratio | O17: ='Valuation (Downside)'!F70 -> 22.8102 | P17: ='Valuation (Downside)'!G70 -> 17.776956 | Q17: ='Valuation (Downside)'!H70 -> 18.234041 | R17: ='Valuation (Downside)'!I70 -> 20.210358 | S17: ='Valuation (Downside)'!J70 -> 21.290638 | T17: ='Valuation (Downside)'!K70 -> 23.282176 | U17: ='Valuation (Downside)'!L70 -> 24.585977 | V17: ='Valuation (Downside)'!M70 -> 26.094722 | X17: Δ OpEx % Revenue | Z17: ='3-Statement (Downside)'!L14 -> 0.015 | AA17: ='3-Statement (Downside)'!M14 -> 0.012 | AB17: ='3-Statement (Downside)'!N14 -> 0.008 | AC17: ='3-Statement (Downside)'!O14 -> 0.005 | AD17: ='3-Statement (Downside)'!P14 -> 0 | AE17: ='3-Statement (Downside)'!Q14 -> 0 | AF17: ='3-Statement (Downside)'!R14 -> 0
D18: ='Valuation (Base)'!D76 -> Fixed Charge Coverage Ratio | E18: ='Valuation (Base)'!F76 -> 11.895128 | F18: ='Valuation (Base)'!G76 -> 13.513415 | G18: ='Valuation (Base)'!H76 -> 13.787291 | H18: ='Valuation (Base)'!I76 -> 14.394623 | I18: ='Valuation (Base)'!J76 -> 14.26465 | J18: ='Valuation (Base)'!K76 -> 14.365361 | K18: ='Valuation (Base)'!L76 -> 15.039268 | L18: ='Valuation (Base)'!M76 -> 15.324398 | N18: =D18 -> Fixed Charge Coverage Ratio | O18: ='Valuation (Downside)'!F76 -> 11.895128 | P18: ='Valuation (Downside)'!G76 -> 10.833384 | Q18: ='Valuation (Downside)'!H76 -> 11.171563 | R18: ='Valuation (Downside)'!I76 -> 12.051782 | S18: ='Valuation (Downside)'!J76 -> 12.335028 | T18: ='Valuation (Downside)'!K76 -> 13.091308 | U18: ='Valuation (Downside)'!L76 -> 13.689609 | V18: ='Valuation (Downside)'!M76 -> 14.00353 | X18: Δ NWC % Revenue | Z18: ='3-Statement (Downside)'!L23 -> 0.024 | AA18: ='3-Statement (Downside)'!M23 -> 0.018 | AB18: ='3-Statement (Downside)'!N23 -> 0.006 | AC18: ='3-Statement (Downside)'!O23 -> 0.003 | AD18: ='3-Statement (Downside)'!P23 -> 0 | AE18: ='3-Statement (Downside)'!Q23 -> 0 | AF18: ='3-Statement (Downside)'!R23 -> 0
D19: ='Valuation (Base)'!D80 -> Current Ratio | E19: ='Valuation (Base)'!F80 -> 2.1056234 | F19: ='Valuation (Base)'!G80 -> 2.0872094 | G19: ='Valuation (Base)'!H80 -> 2.1184821 | H19: ='Valuation (Base)'!I80 -> 2.1661126 | I19: ='Valuation (Base)'!J80 -> 2.1833194 | J19: ='Valuation (Base)'!K80 -> 2.215593 | K19: ='Valuation (Base)'!L80 -> 2.2399978 | L19: ='Valuation (Base)'!M80 -> 2.2678933 | N19: =D19 -> Current Ratio | O19: ='Valuation (Downside)'!F80 -> 2.1056234 | P19: ='Valuation (Downside)'!G80 -> 2.1584917 | Q19: ='Valuation (Downside)'!H80 -> 2.1720491 | R19: ='Valuation (Downside)'!I80 -> 2.1840386 | S19: ='Valuation (Downside)'!J80 -> 2.1923235 | T19: ='Valuation (Downside)'!K80 -> 2.215593 | U19: ='Valuation (Downside)'!L80 -> 2.2399978 | V19: ='Valuation (Downside)'!M80 -> 2.2678933 | X19: Δ CapEx % Revenue | Z19: ='3-Statement (Downside)'!L25 -> -0.003 | AA19: ='3-Statement (Downside)'!M25 -> -0.002 | AB19: ='3-Statement (Downside)'!N25 -> -0.001 | AC19: ='3-Statement (Downside)'!O25 -> -0.001 | AD19: ='3-Statement (Downside)'!P25 -> 0 | AE19: ='3-Statement (Downside)'!Q25 -> 0 | AF19: ='3-Statement (Downside)'!R25 -> 0
D20: ='Valuation (Base)'!D86 -> Quick Ratio | E20: ='Valuation (Base)'!F86 -> 0.77170049 | F20: ='Valuation (Base)'!G86 -> 0.7656641 | G20: ='Valuation (Base)'!H86 -> 0.77591577 | H20: ='Valuation (Base)'!I86 -> 0.79152985 | I20: ='Valuation (Base)'!J86 -> 0.7971705 | J20: ='Valuation (Base)'!K86 -> 0.8077503 | K20: ='Valuation (Base)'!L86 -> 0.8157506 | L20: ='Valuation (Base)'!M86 -> 0.8248952 | N20: =D20 -> Quick Ratio | O20: ='Valuation (Downside)'!F86 -> 0.77170049 | P20: ='Valuation (Downside)'!G86 -> 0.78903157 | Q20: ='Valuation (Downside)'!H86 -> 0.79347593 | R20: ='Valuation (Downside)'!I86 -> 0.79740626 | S20: ='Valuation (Downside)'!J86 -> 0.80012218 | T20: ='Valuation (Downside)'!K86 -> 0.8077503 | U20: ='Valuation (Downside)'!L86 -> 0.8157506 | V20: ='Valuation (Downside)'!M86 -> 0.8248952 | X20: Δ Other % Revenue | Z20: ='3-Statement (Downside)'!L28 -> -0.004 | AA20: ='3-Statement (Downside)'!M28 -> -0.004 | AB20: ='3-Statement (Downside)'!N28 -> -0.003 | AC20: ='3-Statement (Downside)'!O28 -> -0.002 | AD20: ='3-Statement (Downside)'!P28 -> 0 | AE20: ='3-Statement (Downside)'!Q28 -> 0 | AF20: ='3-Statement (Downside)'!R28 -> 0

Sheet Valuation (Base)
D3: VALUATION
E4: ='3-Statement (Base)'!J2 -> Q4-24 | F4: ='3-Statement (Base)'!K2 -> 45657 | G4: ='3-Statement (Base)'!L2 -> 46022 | H4: ='3-Statement (Base)'!M2 -> 46387 | I4: ='3-Statement (Base)'!N2 -> 46752 | J4: ='3-Statement (Base)'!O2 -> 47118 | K4: ='3-Statement (Base)'!P2 -> 47483 | L4: ='3-Statement (Base)'!Q2 -> 47848 | M4: ='3-Statement (Base)'!R2 -> 48213
D5: Revenue | E5: ='3-Statement (Base)'!J43 -> 952178.75 | F5: ='3-Statement (Base)'!K43 -> 3820845.7 | G5: ='3-Statement (Base)'!L43 -> 3800977.3 | H5: ='3-Statement (Base)'!M43 -> 3978863.1 | I5: ='3-Statement (Base)'!N43 -> 4240672.3 | J5: ='3-Statement (Base)'!O43 -> 4373829.4 | K5: ='3-Statement (Base)'!P43 -> 4592520.9 | L5: ='3-Statement (Base)'!Q43 -> 4765934.4 | M5: ='3-Statement (Base)'!R43 -> 4986845
D6: Cost of Goods Sold | E6: ='3-Statement (Base)'!J46 -> -559738.78 | F6: ='3-Statement (Base)'!K46 -> -2246230.8 | G6: ='3-Statement (Base)'!L46 -> -2222863.2 | H6: ='3-Statement (Base)'!M46 -> -2331350.5 | I6: ='3-Statement (Base)'!N46 -> -2482296.6 | J6: ='3-Statement (Base)'!O46 -> -2566738 | K6: ='3-Statement (Base)'!P46 -> -2691979.9 | L6: ='3-Statement (Base)'!Q46 -> -2791987.3 | M6: ='3-Statement (Base)'!R46 -> -2922406.9
D7: Operating Expenses | E7: ='3-Statement (Base)'!J47 -> -289178.76 | F7: ='3-Statement (Base)'!K47 -> -1160037.8 | G7: ='3-Statement (Base)'!L47 -> -1137677.8 | H7: ='3-Statement (Base)'!M47 -> -1185928.2 | I7: ='3-Statement (Base)'!N47 -> -1256691.8 | J7: ='3-Statement (Base)'!O47 -> -1298569.4 | K7: ='3-Statement (Base)'!P47 -> -1372442.2 | L7: ='3-Statement (Base)'!Q47 -> -1419724 | M7: ='3-Statement (Base)'!R47 -> -1484112.8
D8: Restructuring Costs | E8: ='3-Statement (Base)'!J49 -> -6677.9508 | F8: ='3-Statement (Base)'!K49 -> -18464.951 | G8: ='3-Statement (Base)'!L49 -> -33927.258 | H8: ='3-Statement (Base)'!M49 -> -35289.429 | I8: ='3-Statement (Base)'!N49 -> -31192.044 | J8: ='3-Statement (Base)'!O49 -> -32125.93 | K8: ='3-Statement (Base)'!P49 -> -37397.865 | L8: ='3-Statement (Base)'!Q49 -> -38736.417 | M8: ='3-Statement (Base)'!R49 -> -39735.867
D9: EBIT | E9: =SUM(E5:E8) -> 96583.254 | F9: =SUM(F5:F8) -> 396112.25 | G9: =SUM(G5:G8) -> 406509.1 | H9: =SUM(H5:H8) -> 426294.94 | I9: =SUM(I5:I8) -> 470491.83 | J9: =SUM(J5:J8) -> 476396.03 | K9: =SUM(K5:K8) -> 490700.95 | L9: =SUM(L5:L8) -> 515486.74 | M9: =SUM(M5:M8) -> 540589.51
D10: Net Interest | E10: ='3-Statement (Base)'!J55 -> -4723.6238 | F10: ='3-Statement (Base)'!K55 -> -18790.624 | G10: ='3-Statement (Base)'!L55 -> -18749.482 | H10: ='3-Statement (Base)'!M55 -> -18641.766 | I10: ='3-Statement (Base)'!N55 -> -18398.998 | J10: ='3-Statement (Base)'!O55 -> -18166.8 | K10: ='3-Statement (Base)'!P55 -> -17928.663 | L10: ='3-Statement (Base)'!Q55 -> -17706.956 | M10: ='3-Statement (Base)'!R55 -> -17507.516
D11: Other Income (Expense) | E11: ='3-Statement (Base)'!J54 -> -6260.0937 | F11: ='3-Statement (Base)'!K54 -> -25113.094 | G11: ='3-Statement (Base)'!L54 -> -19944.303 | H11: ='3-Statement (Base)'!M54 -> -20980.147 | I11: ='3-Statement (Base)'!N54 -> -23055.523 | J11: ='3-Statement (Base)'!O54 -> -24400.953 | K11: ='3-Statement (Base)'!P54 -> -25817.608 | L11: ='3-Statement (Base)'!Q54 -> -25886.011 | M11: ='3-Statement (Base)'!R54 -> -27269.709
D12: Taxes | E12: ='3-Statement (Base)'!J58 -> -20686.393 | F12: ='3-Statement (Base)'!K58 -> -85290.393 | G12: ='3-Statement (Base)'!L58 -> -90212.334 | H12: ='3-Statement (Base)'!M58 -> -94719 | I12: ='3-Statement (Base)'!N58 -> -105155.72 | J12: ='3-Statement (Base)'!O58 -> -106314.79 | K12: ='3-Statement (Base)'!P58 -> -109284.16 | L12: ='3-Statement (Base)'!Q58 -> -115603.72 | M12: ='3-Statement (Base)'!R58 -> -121434.78
D13: Net Income | E13: =SUM(E9:E12) -> 64913.144 | F13: =SUM(F9:F12) -> 266918.14 | G13: =SUM(G9:G12) -> 277602.98 | H13: =SUM(H9:H12) -> 291954.03 | I13: =SUM(I9:I12) -> 323881.59 | J13: =SUM(J9:J12) -> 327513.49 | K13: =SUM(K9:K12) -> 337670.52 | L13: =SUM(L9:L12) -> 356290.05 | M13: =SUM(M9:M12) -> 374377.5
D15: Cash Flow from Operations | E15: ='3-Statement (Base)'!J98 -> 51395.363 | F15: ='3-Statement (Base)'!K98 -> 354828.36 | G15: ='3-Statement (Base)'!L98 -> 402710.6 | H15: ='3-Statement (Base)'!M98 -> 356238.35 | I15: ='3-Statement (Base)'!N98 -> 370630.43 | J15: ='3-Statement (Base)'!O98 -> 415587.95 | K15: ='3-Statement (Base)'!P98 -> 405666.36 | L15: ='3-Statement (Base)'!Q98 -> 441303.16 | M15: ='3-Statement (Base)'!R98 -> 455889.97
D16: Capital Expenditures | E16: ='3-Statement (Base)'!J101 -> -24318.379 | F16: ='3-Statement (Base)'!K101 -> -97672.379 | G16: ='3-Statement (Base)'!L101 -> -73395.274 | H16: ='3-Statement (Base)'!M101 -> -80482.712 | I16: ='3-Statement (Base)'!N101 -> -88879.07 | J16: ='3-Statement (Base)'!O101 -> -95461.983 | K16: ='3-Statement (Base)'!P101 -> -99092.467 | L16: ='3-Statement (Base)'!Q101 -> -99034.698 | M16: ='3-Statement (Base)'!R101 -> -105091.41
D17: Free Cash Flow | E17: =SUM(E15:E16) -> 27076.985 | F17: =SUM(F15:F16) -> 257155.98 | G17: =SUM(G15:G16) -> 329315.33 | H17: =SUM(H15:H16) -> 275755.63 | I17: =SUM(I15:I16) -> 281751.36 | J17: =SUM(J15:J16) -> 320125.97 | K17: =SUM(K15:K16) -> 306573.89 | L17: =SUM(L15:L16) -> 342268.46 | M17: =SUM(M15:M16) -> 350798.57
D19: Free Cash Flow | G19: =G17 -> 329315.33 | H19: =H17 -> 275755.63 | I19: =I17 -> 281751.36 | J19: =J17 -> 320125.97 | K19: =K17 -> 306573.89 | L19: =L17 -> 342268.46 | M19: =M17 -> 350798.57
D20: Growth Rate | M20: 0.03
D21: WACC (Given) | M21: 0.093
D22: Terminal Value | M22: =(M19*(1+M20))/(M21-M20) -> 5735278.1
D23: Discounted Terminal Value | M23: =M22/((1+M21)^COUNT(G19:M19)) -> 3077608.3
D24: Present Value of Cash Flows | M24: =NPV(M21,G19:M19) -> 1557723.5
D25: Enterprise Value | M25: =M24+M23 -> 4635331.9
D27: Enterprise Value | M27: =M25 -> 4635331.9
D28: Total Debt | M28: =-M48 -> -589426.28
D29: Cash & Cash Equivalents | M29: ='3-Statement (Base)'!R68 -> 25000
D30: Net Debt | M30: =M28+M29 -> -564426.28
D31: Minority Interest | M31: =-'3-Statement (Base)'!R84 -> -24962.83
D32: Implied Equity Value | M32: =M27+M30+M31 -> 4045942.7
D34: Implied Equity Value | M34: =M32 -> 4045942.7
D35: Weighted-Average Shares Outstanding | M35: 55900
D36: Per-Share Value | M36: =M34/M35 -> 72.378224
D38: Net Income | F38: =F13 -> 266918.14
D39: Shares | F39: =$M$35 -> 55900
D40: EPS | F40: =F38/F39 -> 4.7749221
D41: Market Capitalization | F41: =F38*F42 -> 4129223.7
D42: 3-Year Average PE Ratio | F42: 15.47
D43: Per-Share Value | F43: =F41/F39 -> 73.868044
D44: Average Per-Share Value | F44: =AVERAGE(F43,M36) -> 73.123134
D46: SUMMARY OUTPUTS
E47: =E4 -> Q4-24 | F47: =F4 -> 45657 | G47: =G4 -> 46022 | H47: =H4 -> 46387 | I47: =I4 -> 46752 | J47: =J4 -> 47118 | K47: =K4 -> 47483 | L47: =L4 -> 47848 | M47: =M4 -> 48213
D48: Total Debt | E48: ='3-Statement (Base)'!J76+'3-Statement (Base)'!J77+'3-Statement (Base)'!J78 -> 526474.58 | F48: ='3-Statement (Base)'!K76+'3-Statement (Base)'!K77+'3-Statement (Base)'!K78 -> 526474.58 | G48: ='3-Statement (Base)'!L76+'3-Statement (Base)'!L77+'3-Statement (Base)'!L78 -> 513660.94 | H48: ='3-Statement (Base)'!M76+'3-Statement (Base)'!M77+'3-Statement (Base)'!M78 -> 528197.99 | I48: ='3-Statement (Base)'!N76+'3-Statement (Base)'!N77+'3-Statement (Base)'!N78 -> 540957.74 | J48: ='3-Statement (Base)'!O76+'3-Statement (Base)'!O77+'3-Statement (Base)'!O78 -> 555238.82 | K48: ='3-Statement (Base)'!P76+'3-Statement (Base)'!P77+'3-Statement (Base)'!P78 -> 566564 | L48: ='3-Statement (Base)'!Q76+'3-Statement (Base)'!Q77+'3-Statement (Base)'!Q78 -> 573762.59 | M48: ='3-Statement (Base)'!R76+'3-Statement (Base)'!R77+'3-Statement (Base)'!R78 -> 589426.28
...

Sheet 3-Statement (Base)
C1: ACTUALS | D1: ACTUALS | E1: ACTUALS | F1: ACTUALS | G1: ACTUALS | H1: ACTUALS | I1: ACTUALS | J1: FORECAST | K1: FORECAST | L1: FORECAST | M1: FORECAST | N1: FORECAST | O1: FORECAST | P1: FORECAST | Q1: FORECAST | R1: FORECAST
B2: Drivers: | C2: 44196 | D2: =EOMONTH(C2,12) -> 44561 | E2: =EOMONTH(D2,12) -> 44926 | F2: =EOMONTH(E2,12) -> 45291 | G2: Q1-24 | H2: Q2-24 | I2: Q3-24 | J2: Q4-24 | K2: =EOMONTH(F2,12) -> 45657 | L2: =EOMONTH(K2,12) -> 46022 | M2: =EOMONTH(L2,12) -> 46387 | N2: =EOMONTH(M2,12) -> 46752 | O2: =EOMONTH(N2,12) -> 47118 | P2: =EOMONTH(O2,12) -> 47483 | Q2: =EOMONTH(P2,12) -> 47848 | R2: =EOMONTH(Q2,12) -> 48213
B4: Market Size:
B5: Growth Rate:
B7: Market Share %:
B9: Revenue | C9: =C43 -> 3192399 | D9: =D43 -> 3243224 | E9: =E43 -> 3691893 | F9: =F43 -> 4009282 | G9: =G43 -> 953969 | H9: =H43 -> 935348 | I9: =I43 -> 979350 | J9: =K9-I9-H9-G9 -> 952178.75 | K9: =F9*(1+K10) -> 3820845.7 | L9: =K9*(1+L10) -> 3800977.3 | M9: =L9*(1+M10) -> 3978863.1 | N9: =M9*(1+N10) -> 4240672.3 | O9: =N9*(1+O10) -> 4373829.4 | P9: =O9*(1+P10) -> 4592520.9 | Q9: =P9*(1+Q10) -> 4765934.4 | R9: =Q9*(1+R10) -> 4986845
B10: Growth Rate: | D10: =D9/C9-1 -> 0.015920629 | E10: =E9/D9-1 -> 0.13834043 | F10: =F9/E9-1 -> 0.085969176 | H10: =H9/G9-1 -> -0.019519502 | I10: =I9/H9-1 -> 0.047043453 | J10: =J9/I9-1 -> -0.027744171 | K10: -0.047 | L10: -0.0052 | M10: 0.0468 | N10: 0.0658 | O10: 0.0314 | P10: 0.05 | Q10: =AVERAGE(L10:P10) -> 0.03776 | R10: =AVERAGE(M10:Q10) -> 0.046352
B12: COGS % Revenue: | C12: =-C46/C43 -> 0.57921237 | D12: =-D46/D43 -> 0.58883044 | E12: =-E46/E43 -> 0.5779271 | F12: =-F46/F43 -> 0.59020967 | G12: =-G46/G43 -> 0.58791428 | H12: =-H46/H43 -> 0.5845279 | I12: =-I46/I43 -> 0.59110941 | J12: =AVERAGE(G12:I12) -> 0.58785053 | K12: =-K46/K43 -> 0.58788837 | L12: =AVERAGE(C12:F12,K12) -> 0.58481359 | M12: =AVERAGE(K12:L12,D12:F12) -> 0.58593383 | N12: =AVERAGE(K12:M12,E12:F12) -> 0.58535451 | O12: =AVERAGE(K12:N12,F12) -> 0.58683999 | P12: =AVERAGE(K12:O12) -> 0.58616606 | Q12: =AVERAGE(L12:P12) -> 0.5858216 | R12: =AVERAGE(M12:Q12) -> 0.5860232
B13: OpEx % Revenue: | C13: =-C47/C44 -> 0.30558618 | D13: =-D47/D44 -> 0.30662945 | E13: =-E47/E44 -> 0.29357893 | F13: =-F47/F44 -> 0.2871574 | G13: =-G47/G44 -> 0.30465665 | H13: =-H47/H44 -> 0.3113654 | I13: =-I47/I44 -> 0.29508449 | J13: =AVERAGE(G13:I13) -> 0.30370218 | K13: =-K47/K44 -> 0.30360759 | L13: =AVERAGE(C13:F13,K13) -> 0.29931191 | M13: =AVERAGE(K13:L13,D13:F13) -> 0.29805706 | N13: =AVERAGE(K13:M13,E13:F13) -> 0.29634258 | O13: =AVERAGE(K13:N13,F13) -> 0.29689531 | P13: =AVERAGE(K13:O13) -> 0.29884289 | Q13: =AVERAGE(L13:P13) -> 0.29788995 | R13: =AVERAGE(M13:Q13) -> 0.29760556
B14: Impairment % Revenue: | C14: =-C48/C43 -> 0 | D14: =-D48/D43 -> 0.0018148608 | E14: =-E48/E43 -> 0 | F14: =-F48/F43 -> 0 | G14: =-G48/G43 -> 0 | H14: =-H48/H43 -> 0 | I14: =-I48/I43 -> 0 | J14: =AVERAGE(G14:I14) -> 0 | K14: =-K48/K43 -> 0 | L14: =AVERAGE(C14:F14,K14) -> 0.00036297215 | M14: =AVERAGE(K14:L14,D14:F14) -> 0.00043556658 | N14: =AVERAGE(K14:M14,E14:F14) -> 0.00015970775 | O14: =AVERAGE(K14:N14,F14) -> 0.0001916493 | P14: =AVERAGE(K14:O14) -> 0.00022997916 | Q14: =AVERAGE(L14:P14) -> 0.00027597499 | R14: =AVERAGE(M14:Q14) -> 0.00025857555
B15: Restructuring % of Revenue: | C15: =C49/C46 -> 0.0092094596 | D15: =D49/D46 -> 0.016438107 | E15: =E49/E46 -> 0.0074075116 | F15: =F49/F46 -> 0.0033541575 | G15: =G49/G46 -> 0.0016332294 | H15: =H49/H46 -> 0.011305253 | I15: =I49/I46 -> 0.00810153 | J15: =AVERAGE(G15:I15) -> 0.0070133374 | K15: =K49/K46 -> 0.0082204157 | L15: =AVERAGE(C15:F15,K15) -> 0.0089259302 | M15: =AVERAGE(K15:L15,D15:F15) -> 0.0088692243 | N15: =AVERAGE(K15:M15,E15:F15) -> 0.0073554479 | O15: =AVERAGE(K15:N15,F15) -> 0.0073450351 | P15: =AVERAGE(K15:O15) -> 0.0081432106 | Q15: =AVERAGE(L15:P15) -> 0.0081277696 | R15: =AVERAGE(M15:Q15) -> 0.0079681375
B16: Gain on Sale % Revenue: | C16: =-C50/C43 -> 0 | D16: =-D50/D43 -> 0 | E16: =-E50/E43 -> -0.0027443916 | F16: =-F50/F43 -> 0 | G16: =-G50/G43 -> 0 | H16: =-H50/H43 -> 0 | I16: =-I50/I43 -> 0 | J16: =AVERAGE(G16:I16) -> 0 | K16: =-K50/K43 -> 0 | L16: =AVERAGE(C16:F16,K16) -> -0.00054887831 | M16: =AVERAGE(K16:L16,D16:F16) -> -0.00065865398 | N16: =AVERAGE(K16:M16,E16:F16) -> -0.00079038477 | O16: =AVERAGE(K16:N16,F16) -> -0.00039958341 | P16: =AVERAGE(K16:O16) -> -0.00047950009 | Q16: =AVERAGE(L16:P16) -> -0.00057540011 | R16: =AVERAGE(M16:Q16) -> -0.00058070447
B17: Other Income % Revenue: | C17: =C54/C43 -> -0.0051184078 | D17: =D54/D43 -> -0.0044535931 | E17: =E54/E43 -> -0.0047263017 | F17: =F54/F43 -> -0.005364801 | G17: =G54/G43 -> -0.0054456696 | H17: =H54/H43 -> -0.0073854865 | I17: =I54/I43 -> -0.0068923265 | J17: =AVERAGE(G17:I17) -> -0.0065744942 | K17: =K54/K43 -> -0.0065726531 | L17: =AVERAGE(C17:F17,K17) -> -0.0052471513 | M17: =AVERAGE(K17:L17,D17:F17) -> -0.0052729 | N17: =AVERAGE(K17:M17,E17:F17) -> -0.0054367614 | O17: =AVERAGE(K17:N17,F17) -> -0.0055788534 | P17: =AVERAGE(K17:O17) -> -0.0056216639 | Q17: =AVERAGE(L17:P17) -> -0.005431466 | R17: =AVERAGE(M17:Q17) -> -0.0054683289
B18: Tax Rate: | C18: =-C58/C56 -> 0.24679731 | D18: =-D58/D56 -> 0.24426883 | E18: =-E58/E56 -> 0.24527189 | F18: =-F58/F56 -> 0.24782969 | G18: =-G58/G56 -> 0.242997 | H18: =-H58/H56 -> 0.23000438 | I18: =-I58/I56 -> 0.25199295 | J18: =AVERAGE(G18:I18) -> 0.24166478 | K18: =-K58/K56 -> 0.24215879 | L18: =AVERAGE(C18:F18,K18) -> 0.2452653 | M18: =AVERAGE(K18:L18,D18:F18) -> 0.2449589 | N18: =AVERAGE(K18:M18,E18:F18) -> 0.24509691 | O18: =AVERAGE(K18:N18,F18) -> 0.24506192 | P18: =AVERAGE(K18:O18) -> 0.24450837 | Q18: =AVERAGE(L18:P18) -> 0.24497828 | R18: =AVERAGE(M18:Q18) -> 0.24492088
B19: NCI Net Income % Total: | C19: =C61/C60 -> 0.0025460959 | D19: =D61/D60 -> 0.0047261365 | E19: =E61/E60 -> 0.0020441609 | F19: =F61/F60 -> -0.00036723238 | G19: =G61/G60 -> -0.0032114339 | H19: =H61/H60 -> -0.0045805246 | I19: =I61/I60 -> -0.0055109939 | J19: =AVERAGE(G19:I19) -> -0.0044343175 | K19: =K61/K60 -> -0.0025060834 | L19: =AVERAGE(C19:F19,K19) -> 0.0012886155 | M19: =AVERAGE(K19:L19,D19:F19) -> 0.0010371194 | N19: =AVERAGE(K19:M19,E19:F19) -> 0.000299316 | O19: =AVERAGE(K19:N19,F19) -> -4.9652985e-05 | P19: =AVERAGE(K19:O19) -> 1.3862893e-05 | Q19: =AVERAGE(L19:P19) -> 0.00051785216 | R19: =AVERAGE(M19:Q19) -> 0.0003636995
B21: NWC % Revenue: | C21: =C69/C44 -> 0.25876277 | D21: =D69/D44 -> 0.28188432 | E21: =E69/E44 -> 0.29790192 | F21: =F69/F44 -> 0.21149922 | G21: =G69/G44/4 -> 0.22572825 | H21: =H69/H44/4 -> 0.23255649 | I21: =I69/I44/4 -> 0.20670419 | J21: =AVERAGE(G21:I21) -> 0.22166298 | K21: =K69/K44 -> 0.22095922 | L21: =AVERAGE(F21,K21) -> 0.21622922 | M21: =AVERAGE(K21,L21,F21) -> 0.21622922 | N21: =AVERAGE(L21,M21,K21) -> 0.21780589 | O21: =AVERAGE(M21,N21,L21) -> 0.21675477 | P21: =AVERAGE(N21,O21,M21) -> 0.21692996 | Q21: =AVERAGE(O21,P21,N21) -> 0.21716354 | R21: =AVERAGE(P21,Q21,O21) -> 0.21694942
B22: CapEx % Revenue: | C22: =-C101/C44 -> 0.014719651 | D22: =-D101/D44 -> 0.016571782 | E22: =-E101/E44 -> 0.016623721 | F22: =-F101/F44 -> 0.023069717 | G22: =-G101/G44 -> 0.019322431 | H22: =-H101/H44 -> 0.027102212 | I22: =-I101/I44 -> 0.030194517 | J22: =AVERAGE(G22:I22) -> 0.02553972 | K22: =-K101/K44 -> 0.025563026 | L22: =AVERAGE(C22:F22,K22) -> 0.019309579 | M22: =AVERAGE(K22:L22,D22:F22) -> 0.020227565 | N22: =AVERAGE(K22:M22,E22:F22) -> 0.020958722 | O22: =AVERAGE(K22:N22,F22) -> 0.021825722 | P22: =AVERAGE(K22:O22) -> 0.021576923 | Q22: =AVERAGE(L22:P22) -> 0.020779702 | R22: =AVERAGE(M22:Q22) -> 0.021073727
B23: D&A % Revenue: | C23: =C94/C44 -> 0.021638586 | D23: =D94/D44 -> 0.021227643 | E23: =E94/E44 -> 0.019062308 | F23: =F94/F44 -> 0.018738767 | G23: =G94/G44 -> 0.020736523 | H23: =H94/H44 -> 0.022764789 | I23: =I94/I44 -> 0.021085414 | J23: =AVERAGE(G23:I23) -> 0.021528909 | K23: =K94/K44 -> 0.021519939 | L23: =AVERAGE(C23:F23,K23) -> 0.020437448 | M23: =AVERAGE(K23:L23,D23:F23) -> 0.020197221 | N23: =AVERAGE(K23:M23,E23:F23) -> 0.019991137 | O23: =AVERAGE(K23:N23,F23) -> 0.020176902 | P23: =AVERAGE(K23:O23) -> 0.02046453 | Q23: =AVERAGE(L23:P23) -> 0.020253448 | R23: =AVERAGE(M23:Q23) -> 0.020216647
B24: Other Items % Revenue: | C24: =C97/C44 -> 0.011421191 | D24: =D97/D44 -> 0.0039633402 | E24: =E97/E44 -> 0.0080557589 | F24: =F97/F44 -> 0.0090470064 | G24: =G97/G44 -> 0.005879646 | H24: =H97/H44 -> 0.0010830194 | I24: =I97/I44 -> -0.005415837 | J24: =AVERAGE(G24:I24) -> 0.00051560944 | K24: =K97/K44 -> 0.00047344292 | L24: =AVERAGE(C24:F24,K24) -> 0.006592148 | M24: =AVERAGE(K24:L24,D24:F24) -> 0.0056263393 | N24: =AVERAGE(K24:M24,E24:F24) -> 0.0059589391 | O24: =AVERAGE(K24:N24,F24) -> 0.0055395751 | P24: =AVERAGE(K24:O24) -> 0.0048380889 | Q24: =AVERAGE(L24:P24) -> 0.0057110181 | R24: =AVERAGE(M24:Q24) -> 0.0055347921
B25: Acquisitions & Other % Revenue: | C25: =-C102/C43 -> 0.0007160759 | D25: =-D102/D43 -> 0.0067833736 | E25: =-E102/E43 -> 0.0089710076 | F25: =-F102/F43 -> 0.005033819 | G25: =-G102/G43 -> 0 | H25: =-H102/H43 -> 0.010550084 | I25: =-I102/I43 -> -9.1897687e-06 | J25: =AVERAGE(G25:I25) -> 0.0035136314 | K25: =-K102/K43 -> 0.0034559378 | L25: =AVERAGE(C25:F25,K25) -> 0.0049920428 | M25: =AVERAGE(K25:L25,D25:F25) -> 0.0058472361 | N25: =AVERAGE(K25:M25,E25:F25) -> 0.0056600087 | O25: =AVERAGE(K25:N25,F25) -> 0.0049978089 | P25: =AVERAGE(K25:O25) -> 0.0049906068 | Q25: =AVERAGE(L25:P25) -> 0.0052975407 | R25: =AVERAGE(M25:Q25) -> 0.0053586402
B27: Dividends % Net Income: | C27: =-C108/C62 -> 0.66318489 | D27: =-D108/D62 -> 0.77129369 | E27: =-E108/E62 -> 0.4925924 | F27: =-F108/F62 -> 0.51485434 | G27: =-G108/G62 -> 0.68049027 | H27: =-H108/H62 -> 0.75625333 | I27: =-I108/I62 -> 0.65171188 | J27: =AVERAGE(G27:I27) -> 0.69615183 | K27: =-K108/K62 -> 0.6940755 | L27: =AVERAGE(C27:F27,K27) -> 0.62720016 | M27: =AVERAGE(K27:L27,D27:F27) -> 0.62000322 | N27: =AVERAGE(K27:M27,E27:F27) -> 0.58974512 | O27: =AVERAGE(K27:N27,F27) -> 0.60917567 | P27: =AVERAGE(K27:O27) -> 0.62803993 | Q27: =AVERAGE(L27:P27) -> 0.61483282 | R27: =AVERAGE(M27:Q27) -> 0.61235935
B28: Stock Repurchases % Net Income: | C28: =-C109/C62 -> 0.013714723 | D28: =-D109/D62 -> 0.3285325 | E28: =-E109/E62 -> 0.080518326 | F28: =-F109/F62 -> 0.27904951 | G28: =-G109/G62 -> 1.9040375 | H28: =-H109/H62 -> 0.26892169 | I28: =-I109/I62 -> 0.25784813 | J28: 0 | K28: =-K109/K62 -> 0.6247163 | L28: 0.45 | M28: 0.3 | N28: 0.25 | O28: 0.35 | P28: 0.25 | Q28: 0.3 | R28: 0.3 | S28: Set to maintain capital structure
B29: Other Items % Debt Issuances: | C29: =C111/(C107+C106) -> 0.10910804 | D29: =D111/(D107+D106) -> 0.20243173 | E29: =E111/(E107+E106) -> 5.6242536 | F29: =F111/(F107+F106) -> -0.10019784 | G29: =G111/(G107+G106) -> 0.087705615 | H29: =H111/(H107+H106) -> 0.14705469 | I29: =I111/(I107+I106) -> -0.00048888889 | J29: =AVERAGE(G29:I29) -> 0.078090472 | K29: =K111/(K107+K106) -> 0.12855637 | L29: =K29 -> 0.12855637 | M29: =L29 -> 0.12855637 | N29: =M29 -> 0.12855637 | O29: =N29 -> 0.12855637 | P29: =O29 -> 0.12855637 | Q29: =P29 -> 0.12855637 | R29: =Q29 -> 0.12855637
B31: Total Cash Flow Before Revolver | J31: =I68+J98+J103+SUM(J107:J111)+J114 -> 4127.5042 | K31: =J68+K98+K103+SUM(K107:K111)+K114 -> -61924.496 | L31: =K68+L98+L103+SUM(L107:L111)+L114 -> 35655.546 | M31: =L68+M98+M103+SUM(M107:M111)+M114 -> 8326.2324 | N31: =M68+N98+N103+SUM(N107:N111)+N114 -> 10124.675 | O31: =N68+O98+O103+SUM(O107:O111)+O114 -> 8624.2992 | P31: =O68+P98+P103+SUM(P107:P111)+P114 -> 11600.945 | Q31: =P68+Q98+Q103+SUM(Q107:Q111)+Q114 -> 15748.062 | R31: =Q68+R98+R103+SUM(R107:R111)+R114 -> 7303.2909
B32: Revolver Borrowing to Zero | J32: =-MIN(J31,I76) -> -4127.5042 | K32: =-MIN(K31,J76) -> 61924.496 | L32: =-MIN(L31,K76) -> -35655.546 | M32: =-MIN(M31,L76) -> -8326.2324 | N32: =-MIN(N31,M76) -> -10124.675 | O32: =-MIN(O31,N76) -> -8624.2992 | P32: =-MIN(P31,O76) -> -11600.945 | Q32: =-MIN(Q31,P76) -> -15748.062 | R32: =-MIN(R31,Q76) -> -7303.2909
B33: Estimated Minimum Cash Balance | J33: 25000 | K33: 25000 | L33: 25000 | M33: 25000 | N33: 25000 | O33: 25000 | P33: 25000 | Q33: 25000 | R33: 25000 | S33: Estimate based on historicals
B34: Total Revolver Borrowing Needed | J34: =SUM(J32:J33) -> 20872.496 | K34: =SUM(K32:K33) -> 86924.496 | L34: =SUM(L32:L33) -> -10655.546 | M34: =SUM(M32:M33) -> 16673.768 | N34: =SUM(N32:N33) -> 14875.325 | O34: =SUM(O32:O33) -> 16375.701 | P34: =SUM(P32:P33) -> 13399.055 | Q34: =SUM(Q32:Q33) -> 9251.9376 | R34: =SUM(R32:R33) -> 17696.709
B36: Revolver Maximum Balance | I36: 600000 | J36: 600000 | K36: 600000 | L36: 600000 | M36: 600000 | N36: 600000 | O36: 600000 | P36: 600000 | Q36: 600000 | R36: 600000
B37: Revolver Utilization | I37: =I76 -> 81300 | J37: =J76 -> 102172.5 | K37: =K76 -> 102172.5 | L37: =L76 -> 91516.95 | M37: =M76 -> 108190.72 | N37: =N76 -> 123066.04 | O37: =O76 -> 139441.74 | P37: =P76 -> 152840.8 | ... R37: =R76 -> 179789.44
B38: Net Revolver Balance | I38: =I36-I37 -> 518700 | J38: =J36-J37 -> 497827.5 | K38: =K36-K37 -> 497827.5 | L38: =L36-L37 -> 508483.05 | M38: =M36-M37 -> 491809.28 | N38: =N36-N37 -> 476933.96 | O38: =O36-O37 -> 460558.26 | P38: =P36-P37 -> 447159.2 | ... R38: =R36-R37 -> 420210.56
B39: 50 Bps on Unutilized Revolver | I39: =I38*0.005 -> 2593.5 | J39: =J38*0.005 -> 2489.1375 | K39: =K38*0.005 -> 2489.1375 | L39: =L38*0.005 -> 2542.4153 | M39: =M38*0.005 -> 2459.0464 | N39: =N38*0.005 -> 2384.6698 | O39: =O38*0.005 -> 2302.7913 | P39: =P38*0.005 -> 2235.796 | ... R39: =R38*0.005 -> 2101.0528
B41: Income Statement: | C41: =C$2 -> 44196 | D41: =D$2 -> 44561 | E41: =E$2 -> 44926 | F41: =F$2 -> 45291 | G41: =G$2 -> Q1-24 | H41: =H$2 -> Q2-24 | I41: =I$2 -> Q3-24 | J41: =J$2 -> Q4-24 | ... R41: =R$2 -> 48213
B43: Revenue: | C43: ='Income Statement'!C6 -> 3192399 | D43: ='Income Statement'!D6 -> 3243224 | E43: ='Income Statement'!E6 -> 3691893 | F43: ='Income Statement'!F6 -> 4009282 | G43: ='Income Statement'!G6 -> 953969 | H43: ='Income Statement'!H6 -> 935348 | I43: ='Income Statement'!I6 -> 979350 | J43: =J9 -> 952178.75 | K43: =SUM(G43:J43) -> 3820845.7 | L43: =L9 -> 3800977.3 | M43: =M9 -> 3978863.1 | N43: =N9 -> 4240672.3 | O43: =O9 -> 4373829.4 | P43: =P9 -> 4592520.9 | Q43: =Q9 -> 4765934.4 | R43: =R9 -> 4986845
B44: Total Revenue: | C44: =SUM(C43:C43) -> 3192399 | D44: =SUM(D43:D43) -> 3243224 | E44: =SUM(E43:E43) -> 3691893 | F44: =SUM(F43:F43) -> 4009282 | G44: =SUM(G43:G43) -> 953969 | H44: =SUM(H43:H43) -> 935348 | I44: =SUM(I43:I43) -> 979350 | J44: =SUM(J43:J43) -> 952178.75 | ... R44: =SUM(R43:R43) -> 4986845
B46: Cost of Sales: | C46: =-'Income Statement'!C7 -> -1849077 | D46: =-'Income Statement'!D7 -> -1909709 | E46: =-'Income Statement'!E7 -> -2133645 | F46: =-'Income Statement'!F7 -> -2366317 | G46: =-'Income Statement'!G7 -> -560852 | H46: =-'Income Statement'!H7 -> -546737 | I46: =-'Income Statement'!I7 -> -578903 | J46: =-J$43*J12 -> -559738.78 | K46: =SUM(G46:J46) -> -2246230.8 | L46: =-L$43*L12 -> -2222863.2 | M46: =-M$43*M12 -> -2331350.5 | N46: =-N$43*N12 -> -2482296.6 | O46: =-O$43*O12 -> -2566738 | P46: =-P$43*P12 -> -2691979.9 | Q46: =-Q$43*Q12 -> -2791987.3 | R46: =-R$43*R12 -> -2922406.9
B47: Operating Expenses: | C47: =-'Income Statement'!C11 -> -975553 | D47: =-'Income Statement'!D11 -> -994468 | E47: =-'Income Statement'!E11 -> -1083862 | F47: =-'Income Statement'!F11 -> -1151295 | G47: =-'Income Statement'!G11 -> -290633 | H47: =-'Income Statement'!H11 -> -291235 | I47: =-'Income Statement'!I11 -> -288991 | J47: =-J$43*J13 -> -289178.76 | K47: =SUM(G47:J47) -> -1160037.8 | L47: =-L$43*L13 -> -1137677.8 | M47: =-M$43*M13 -> -1185928.2 | N47: =-N$43*N13 -> -1256691.8 | O47: =-O$43*O13 -> -1298569.4 | P47: =-P$43*P13 -> -1372442.2 | Q47: =-Q$43*Q13 -> -1419724 | R47: =-R$43*R13 -> -1484112.8
B48: Impairment Loss: | C48: =-'Income Statement'!C12 -> 0 | D48: =-'Income Statement'!D12 -> -5886 | E48: =-'Income Statement'!E12 -> 0 | F48: =-'Income Statement'!F12 -> 0 | G48: =-'Income Statement'!G12 -> 0 | H48: =-'Income Statement'!H12 -> 0 | I48: =-'Income Statement'!I12 -> 0 | J48: =-J$43*J14 -> 0 | K48: =SUM(G48:J48) -> 0 | L48: =K48 -> 0 | M48: =L48 -> 0 | N48: =M48 -> 0 | O48: =N48 -> 0 | P48: =O48 -> 0 | Q48: =P48 -> 0 | R48: =Q48 -> 0
B49: Restructuring Costs: | C49: =-'Income Statement'!C13 -> -17029 | D49: =-'Income Statement'!D13 -> -31392 | E49: =-'Income Statement'!E13 -> -15805 | F49: =-'Income Statement'!F13 -> -7937 | G49: =-'Income Statement'!G13 -> -916 | H49: =-'Income Statement'!H13 -> -6181 | I49: =-'Income Statement'!I13 -> -4690 | J49: =-J$43*J15 -> -6677.9508 | K49: =SUM(G49:J49) -> -18464.951 | L49: =-L$43*L15 -> -33927.258 | M49: =-M$43*M15 -> -35289.429 | N49: =-N$43*N15 -> -31192.044 | O49: =-O$43*O15 -> -32125.93 | P49: =-P$43*P15 -> -37397.865 | Q49: =-Q$43*Q15 -> -38736.417 | R49: =-R$43*R15 -> -39735.867
B50: Gain on Sale of Property: | C50: =-'Income Statement'!C14 -> 0 | D50: =-'Income Statement'!D14 -> 0 | E50: =-'Income Statement'!E14 -> 10132 | F50: =-'Income Statement'!F14 -> 0 | G50: =-'Income Statement'!G14 -> 0 | H50: =-'Income Statement'!H14 -> 0 | I50: =-'Income Statement'!I14 -> 0 | J50: =-J$43*J16 -> 0 | K50: =SUM(G50:J50) -> 0 | L50: =K50 -> 0 | M50: =L50 -> 0 | N50: =M50 -> 0 | O50: =N50 -> 0 | P50: =O50 -> 0 | Q50: =P50 -> 0 | R50: =Q50 -> 0
B51: Operating Income: | C51: =C44+SUM(C46:C50) -> 350740 | D51: =D44+SUM(D46:D50) -> 301769 | E51: =E44+SUM(E46:E50) -> 468713 | F51: =F44+SUM(F46:F50) -> 483733 | G51: =G44+SUM(G46:G50) -> 101568 | H51: =H44+SUM(H46:H50) -> 91195 | I51: =I44+SUM(I46:I50) -> 106766 | J51: =J44+SUM(J46:J50) -> 96583.254 | ... R51: =R44+SUM(R46:R50) -> 540589.51
...

Sheet Valuation (Downside)
D3: VALUATION
E4: ='3-Statement (Downside)'!J2 -> Q4-24 | F4: ='3-Statement (Downside)'!K2 -> 45657 | G4: ='3-Statement (Downside)'!L2 -> 46022 | H4: ='3-Statement (Downside)'!M2 -> 46387 | I4: ='3-Statement (Downside)'!N2 -> 46752 | J4: ='3-Statement (Downside)'!O2 -> 47118 | K4: ='3-Statement (Downside)'!P2 -> 47483 | L4: ='3-Statement (Downside)'!Q2 -> 47848 | M4: ='3-Statement (Downside)'!R2 -> 48213
D5: Revenue | E5: ='3-Statement (Downside)'!J48 -> 952178.75 | F5: ='3-Statement (Downside)'!K48 -> 3820845.7 | G5: ='3-Statement (Downside)'!L48 -> 3629803.5 | H5: ='3-Statement (Downside)'!M48 -> 3520909.4 | I5: ='3-Statement (Downside)'!N48 -> 3520909.4 | J5: ='3-Statement (Downside)'!O48 -> 3591327.5 | K5: ='3-Statement (Downside)'!P48 -> 3699067.4 | L5: ='3-Statement (Downside)'!Q48 -> 3838744.2 | M5: ='3-Statement (Downside)'!R48 -> 4016677.6
D6: Cost of Goods Sold | E6: ='3-Statement (Downside)'!J51 -> -559738.78 | F6: ='3-Statement (Downside)'!K51 -> -2246230.8 | G6: ='3-Statement (Downside)'!L51 -> -2159056.4 | H6: ='3-Statement (Downside)'!M51 -> -2091187.2 | I6: ='3-Statement (Downside)'!N51 -> -2078584.7 | J6: ='3-Statement (Downside)'!O51 -> -2118308.6 | K6: ='3-Statement (Downside)'!P51 -> -2168267.7 | L6: ='3-Statement (Downside)'!Q51 -> -2248819.2 | M6: ='3-Statement (Downside)'!R51 -> -2353866.3
D7: Operating Expenses | E7: ='3-Statement (Downside)'!J52 -> -289178.76 | F7: ='3-Statement (Downside)'!K52 -> -1160037.8 | G7: ='3-Statement (Downside)'!L52 -> -1140890.5 | H7: ='3-Statement (Downside)'!M52 -> -1091682.8 | I7: ='3-Statement (Downside)'!N52 -> -1071562.6 | J7: ='3-Statement (Downside)'!O52 -> -1084204.9 | K7: ='3-Statement (Downside)'!P52 -> -1105440 | L7: ='3-Statement (Downside)'!Q52 -> -1143523.3 | M7: ='3-Statement (Downside)'!R52 -> -1195385.6
D8: Restructuring Costs | E8: ='3-Statement (Downside)'!J54 -> -6677.9508 | F8: ='3-Statement (Downside)'!K54 -> -18464.951 | G8: ='3-Statement (Downside)'!L54 -> -32399.372 | H8: ='3-Statement (Downside)'!M54 -> -31227.735 | I8: ='3-Statement (Downside)'!N54 -> -25897.865 | J8: ='3-Statement (Downside)'!O54 -> -26378.427 | K8: ='3-Statement (Downside)'!P54 -> -30122.285 | L8: ='3-Statement (Downside)'!Q54 -> -31200.428 | M8: ='3-Statement (Downside)'!R54 -> -32005.44
D9: EBIT | E9: =SUM(E5:E8) -> 96583.254 | F9: =SUM(F5:F8) -> 396112.25 | G9: =SUM(G5:G8) -> 297457.21 | H9: =SUM(H5:H8) -> 306811.64 | I9: =SUM(I5:I8) -> 344864.14 | J9: =SUM(J5:J8) -> 362435.57 | K9: =SUM(K5:K8) -> 395237.37 | L9: =SUM(L5:L8) -> 415201.2 | M9: =SUM(M5:M8) -> 435420.34
D10: Net Interest | E10: ='3-Statement (Downside)'!J60 -> -4723.6238 | F10: ='3-Statement (Downside)'!K60 -> -18790.624 | G10: ='3-Statement (Downside)'!L60 -> -18747.69 | H10: ='3-Statement (Downside)'!M60 -> -18589.578 | I10: ='3-Statement (Downside)'!N60 -> -18430.884 | J10: ='3-Statement (Downside)'!O60 -> -18332.077 | K10: ='3-Statement (Downside)'!P60 -> -18153.481 | L10: ='3-Statement (Downside)'!Q60 -> -17996.658 | M10: ='3-Statement (Downside)'!R60 -> -17765.012
D11: Other Income (Expense) | E11: ='3-Statement (Downside)'!J59 -> -6260.0937 | F11: ='3-Statement (Downside)'!K59 -> -25113.094 | G11: ='3-Statement (Downside)'!L59 -> -19046.128 | H11: ='3-Statement (Downside)'!M59 -> -18565.403 | I11: ='3-Statement (Downside)'!N59 -> -19142.344 | J11: ='3-Statement (Downside)'!O59 -> -20035.49 | K11: ='3-Statement (Downside)'!P59 -> -20794.913 | L11: ='3-Statement (Downside)'!Q59 -> -20850.008 | M11: ='3-Statement (Downside)'!R59 -> -21964.514
D12: Taxes | E12: ='3-Statement (Downside)'!J63 -> -20686.393 | F12: ='3-Statement (Downside)'!K63 -> -85290.393 | G12: ='3-Statement (Downside)'!L63 -> -63686.42 | H12: ='3-Statement (Downside)'!M63 -> -66054.8 | I12: ='3-Statement (Downside)'!N63 -> -75316.055 | J12: ='3-Statement (Downside)'!O63 -> -79416.727 | K12: ='3-Statement (Downside)'!P63 -> -87115.634 | L12: ='3-Statement (Downside)'!Q63 -> -92198.686 | M12: ='3-Statement (Downside)'!R63 -> -96912.941
D13: Net Income | E13: =SUM(E9:E12) -> 64913.144 | F13: =SUM(F9:F12) -> 266918.14 | G13: =SUM(G9:G12) -> 195976.97 | H13: =SUM(H9:H12) -> 203601.86 | I13: =SUM(I9:I12) -> 231974.86 | J13: =SUM(J9:J12) -> 244651.28 | K13: =SUM(K9:K12) -> 269173.34 | L13: =SUM(L9:L12) -> 284155.85 | M13: =SUM(M9:M12) -> 298777.87
D15: Cash Flow from Operations | E15: ='3-Statement (Downside)'!J103 -> 51395.363 | F15: ='3-Statement (Downside)'!K103 -> 354828.36 | G15: ='3-Statement (Downside)'!L103 -> 246028.06 | H15: ='3-Statement (Downside)'!M103 -> 328503.4 | I15: ='3-Statement (Downside)'!N103 -> 348427.1 | J15: ='3-Statement (Downside)'!O103 -> 326668.12 | K15: ='3-Statement (Downside)'!P103 -> 350106.44 | L15: ='3-Statement (Downside)'!Q103 -> 351042.82 | M15: ='3-Statement (Downside)'!R103 -> 363724.93
D16: Capital Expenditures | E16: ='3-Statement (Downside)'!J106 -> -24318.379 | F16: ='3-Statement (Downside)'!K106 -> -97672.379 | G16: ='3-Statement (Downside)'!L106 -> -59200.568 | H16: ='3-Statement (Downside)'!M106 -> -64177.604 | I16: ='3-Statement (Downside)'!N106 -> -70272.85 | J16: ='3-Statement (Downside)'!O106 -> -74791.988 | K16: ='3-Statement (Downside)'!P106 -> -79814.491 | L16: ='3-Statement (Downside)'!Q106 -> -79767.96 | M16: ='3-Statement (Downside)'!R106 -> -84646.366
D17: Free Cash Flow | E17: =SUM(E15:E16) -> 27076.985 | F17: =SUM(F15:F16) -> 257155.98 | G17: =SUM(G15:G16) -> 186827.5 | H17: =SUM(H15:H16) -> 264325.8 | I17: =SUM(I15:I16) -> 278154.25 | J17: =SUM(J15:J16) -> 251876.13 | K17: =SUM(K15:K16) -> 270291.95 | L17: =SUM(L15:L16) -> 271274.86 | M17: =SUM(M15:M16) -> 279078.56
D19: Free Cash Flow | G19: =G17 -> 186827.5 | H19: =H17 -> 264325.8 | I19: =I17 -> 278154.25 | J19: =J17 -> 251876.13 | K19: =K17 -> 270291.95 | L19: =L17 -> 271274.86 | M19: =M17 -> 279078.56
D20: Growth Rate | M20: 0.03
D21: WACC (Given) | M21: 0.093
D22: Terminal Value | M22: =(M19*(1+M20))/(M21-M20) -> 4562713
D23: Discounted Terminal Value | M23: =(M22/(1+M21)^COUNT(G19:M19)) -> 2448398
D24: Present Value of Cash Flows | M24: =NPV(M21,G19:M19) -> 1263832.5
D25: Enterprise Value | M25: =M24+M23 -> 3712230.5
D27: Enterprise Value | M27: =M25 -> 3712230.5
D28: Total Debt | M28: =-M48 -> -526567.73
D29: Cash & Cash Equivalents | M29: ='3-Statement (Downside)'!R73 -> 25000
D30: Net Debt | M30: =M28+M29 -> -501567.73
D31: Minority Interest | M31: =-'3-Statement (Downside)'!R89 -> -12060.464
D32: Implied Equity Value | M32: =M27+M30+M31 -> 3198602.3
D34: Implied Equity Value | M34: =M32 -> 3198602.3
D35: Weighted-Average Shares Outstanding | M35: 55900
D36: Per-Share Value | M36: =M34/M35 -> 57.220078
D38: Net Income | F38: =F13 -> 266918.14
D39: Shares | F39: =$M$35 -> 55900
D40: EPS | F40: =F38/F39 -> 4.7749221
D41: Market Capitalization | F41: =F38*F42 -> 3203017.7
D42: Recessionary PE Hypothesis | F42: 12
D43: Per-Share Value | F43: =F41/F39 -> 57.299065
D44: Average Per-Share Value | F44: =AVERAGE(F43,M36) -> 57.259571
D46: SUMMARY OUTPUTS
E47: =E4 -> Q4-24 | F47: =F4 -> 45657 | G47: =G4 -> 46022 | H47: =H4 -> 46387 | I47: =I4 -> 46752 | J47: =J4 -> 47118 | K47: =K4 -> 47483 | L47: =L4 -> 47848 | M47: =M4 -> 48213
D48: Total Debt | E48: ='3-Statement (Downside)'!J81+'3-Statement (Downside)'!J82+'3-Statement (Downside)'!J83 -> 526832.95 | F48: ='3-Statement (Downside)'!K81+'3-Statement (Downside)'!K82+'3-Statement (Downside)'!K83 -> 526832.95 | G48: ='3-Statement (Downside)'!L81+'3-Statement (Downside)'!L82+'3-Statement (Downside)'!L83 -> 524098.46 | H48: ='3-Statement (Downside)'!M81+'3-Statement (Downside)'!M82+'3-Statement (Downside)'!M83 -> 521820.75 | I48: ='3-Statement (Downside)'!N81+'3-Statement (Downside)'!N82+'3-Statement (Downside)'!N83 -> 507902.3 | J48: ='3-Statement (Downside)'!O81+'3-Statement (Downside)'!O82+'3-Statement (Downside)'!O83 -> 510275.08 | K48: ='3-Statement (Downside)'!P81+'3-Statement (Downside)'!P82+'3-Statement (Downside)'!P83 -> 508623.52 | L48: ='3-Statement (Downside)'!Q81+'3-Statement (Downside)'!Q82+'3-Statement (Downside)'!Q83 -> 522263.44 | M48: ='3-Statement (Downside)'!R81+'3-Statement (Downside)'!R82+'3-Statement (Downside)'!R83 -> 526567.73
...

Sheet 3-Statement (Downside)
C1: ACTUALS | D1: ACTUALS | E1: ACTUALS | F1: ACTUALS | G1: ACTUALS | H1: ACTUALS | I1: ACTUALS | J1: FORECAST | K1: FORECAST | L1: FORECAST | M1: FORECAST | N1: FORECAST | O1: FORECAST | P1: FORECAST | Q1: FORECAST | R1: FORECAST
B2: Drivers: | C2: 44196 | D2: =EOMONTH(C2,12) -> 44561 | E2: =EOMONTH(D2,12) -> 44926 | F2: =EOMONTH(E2,12) -> 45291 | G2: Q1-24 | H2: Q2-24 | I2: Q3-24 | J2: Q4-24 | K2: =EOMONTH(F2,12) -> 45657 | L2: =EOMONTH(K2,12) -> 46022 | M2: =EOMONTH(L2,12) -> 46387 | N2: =EOMONTH(M2,12) -> 46752 | O2: =EOMONTH(N2,12) -> 47118 | P2: =EOMONTH(O2,12) -> 47483 | Q2: =EOMONTH(P2,12) -> 47848 | R2: =EOMONTH(Q2,12) -> 48213
B4: Market Size:
B5: Growth Rate:
B7: Market Share %:
B9: Revenue | C9: =C48 -> 3192399 | D9: =D48 -> 3243224 | E9: =E48 -> 3691893 | F9: =F48 -> 4009282 | G9: =G48 -> 953969 | H9: =H48 -> 935348 | I9: =I48 -> 979350 | J9: =K9-I9-H9-G9 -> 952178.75 | K9: =F9*(1+K10) -> 3820845.7 | L9: =K9*(1+L10) -> 3629803.5 | M9: =L9*(1+M10) -> 3520909.4 | N9: =M9*(1+N10) -> 3520909.4 | O9: =N9*(1+O10) -> 3591327.5 | P9: =O9*(1+P10) -> 3699067.4 | Q9: =P9*(1+Q10) -> 3838744.2 | R9: =Q9*(1+R10) -> 4016677.6
B10: Growth Rate: | D10: =D9/C9-1 -> 0.015920629 | E10: =E9/D9-1 -> 0.13834043 | F10: =F9/E9-1 -> 0.085969176 | H10: =H9/G9-1 -> -0.019519502 | I10: =I9/H9-1 -> 0.047043453 | J10: =J9/I9-1 -> -0.027744171 | K10: -0.047 | L10: -0.05 | M10: -0.03 | N10: 0 | O10: 0.02 | P10: 0.03 | Q10: ='3-Statement (Base)'!Q10 -> 0.03776 | R10: ='3-Statement (Base)'!R10 -> 0.046352
B12: Recessionary COGS Adj | L12: 0.01 | M12: 0.008 | N12: 0.005 | O12: 0.003
B13: COGS % Revenue: | C13: =-C51/C48 -> 0.57921237 | D13: =-D51/D48 -> 0.58883044 | E13: =-E51/E48 -> 0.5779271 | F13: =-F51/F48 -> 0.59020967 | G13: =-G51/G48 -> 0.58791428 | H13: =-H51/H48 -> 0.5845279 | I13: =-I51/I48 -> 0.59110941 | J13: =AVERAGE(G13:I13) -> 0.58785053 | K13: =-K51/K48 -> 0.58788837 | L13: ='3-Statement (Base)'!L12+L12 -> 0.59481359 | M13: ='3-Statement (Base)'!M12+M12 -> 0.59393383 | N13: ='3-Statement (Base)'!N12+N12 -> 0.59035451 | O13: ='3-Statement (Base)'!O12+O12 -> 0.58983999 | P13: ='3-Statement (Base)'!P12+P12 -> 0.58616606 | Q13: ='3-Statement (Base)'!Q12+Q12 -> 0.5858216 | R13: ='3-Statement (Base)'!R12+R12 -> 0.5860232
B14: Recessionary OpEx Adj | L14: 0.015 | M14: 0.012 | N14: 0.008 | O14: 0.005
B15: OpEx % Revenue: | C15: =-C52/C49 -> 0.30558618 | D15: =-D52/D49 -> 0.30662945 | E15: =-E52/E49 -> 0.29357893 | F15: =-F52/F49 -> 0.2871574 | G15: =-G52/G49 -> 0.30465665 | H15: =-H52/H49 -> 0.3113654 | I15: =-I52/I49 -> 0.29508449 | J15: =AVERAGE(G15:I15) -> 0.30370218 | K15: =-K52/K49 -> 0.30360759 | L15: ='3-Statement (Base)'!L13+L14 -> 0.31431191 | M15: ='3-Statement (Base)'!M13+M14 -> 0.31005706 | N15: ='3-Statement (Base)'!N13+N14 -> 0.30434258 | O15: ='3-Statement (Base)'!O13+O14 -> 0.30189531 | P15: ='3-Statement (Base)'!P13+P14 -> 0.29884289 | Q15: ='3-Statement (Base)'!Q13+Q14 -> 0.29788995 | R15: ='3-Statement (Base)'!R13+R14 -> 0.29760556
B16: Impairment % Revenue: | C16: =-C53/C48 -> 0 | D16: =-D53/D48 -> 0.0018148608 | E16: =-E53/E48 -> 0 | F16: =-F53/F48 -> 0 | G16: =-G53/G48 -> 0 | H16: =-H53/H48 -> 0 | I16: =-I53/I48 -> 0 | J16: =AVERAGE(G16:I16) -> 0 | K16: =-K53/K48 -> 0 | L16: =AVERAGE(C16:F16,K16) -> 0.00036297215 | M16: =AVERAGE(K16:L16,D16:F16) -> 0.00043556658 | N16: =AVERAGE(K16:M16,E16:F16) -> 0.00015970775 | O16: =AVERAGE(K16:N16,F16) -> 0.0001916493 | P16: =AVERAGE(K16:O16) -> 0.00022997916 | Q16: =AVERAGE(L16:P16) -> 0.00027597499 | R16: =AVERAGE(M16:Q16) -> 0.00025857555
B17: Restructuring % of Revenue: | C17: =C54/C51 -> 0.0092094596 | D17: =D54/D51 -> 0.016438107 | E17: =E54/E51 -> 0.0074075116 | F17: =F54/F51 -> 0.0033541575 | G17: =G54/G51 -> 0.0016332294 | H17: =H54/H51 -> 0.011305253 | I17: =I54/I51 -> 0.00810153 | J17: =AVERAGE(G17:I17) -> 0.0070133374 | K17: =K54/K51 -> 0.0082204157 | L17: =AVERAGE(C17:F17,K17) -> 0.0089259302 | M17: =AVERAGE(K17:L17,D17:F17) -> 0.0088692243 | N17: =AVERAGE(K17:M17,E17:F17) -> 0.0073554479 | O17: =AVERAGE(K17:N17,F17) -> 0.0073450351 | P17: =AVERAGE(K17:O17) -> 0.0081432106 | Q17: =AVERAGE(L17:P17) -> 0.0081277696 | R17: =AVERAGE(M17:Q17) -> 0.0079681375
B18: Gain on Sale % Revenue: | C18: =-C55/C48 -> 0 | D18: =-D55/D48 -> 0 | E18: =-E55/E48 -> -0.0027443916 | F18: =-F55/F48 -> 0 | G18: =-G55/G48 -> 0 | H18: =-H55/H48 -> 0 | I18: =-I55/I48 -> 0 | J18: =AVERAGE(G18:I18) -> 0 | K18: =-K55/K48 -> 0 | L18: =AVERAGE(C18:F18,K18) -> -0.00054887831 | M18: =AVERAGE(K18:L18,D18:F18) -> -0.00065865398 | N18: =AVERAGE(K18:M18,E18:F18) -> -0.00079038477 | O18: =AVERAGE(K18:N18,F18) -> -0.00039958341 | P18: =AVERAGE(K18:O18) -> -0.00047950009 | Q18: =AVERAGE(L18:P18) -> -0.00057540011 | R18: =AVERAGE(M18:Q18) -> -0.00058070447
B19: Other Income % Revenue: | C19: =C59/C48 -> -0.0051184078 | D19: =D59/D48 -> -0.0044535931 | E19: =E59/E48 -> -0.0047263017 | F19: =F59/F48 -> -0.005364801 | G19: =G59/G48 -> -0.0054456696 | H19: =H59/H48 -> -0.0073854865 | I19: =I59/I48 -> -0.0068923265 | J19: =AVERAGE(G19:I19) -> -0.0065744942 | K19: =K59/K48 -> -0.0065726531 | L19: =AVERAGE(C19:F19,K19) -> -0.0052471513 | M19: =AVERAGE(K19:L19,D19:F19) -> -0.0052729 | N19: =AVERAGE(K19:M19,E19:F19) -> -0.0054367614 | O19: =AVERAGE(K19:N19,F19) -> -0.0055788534 | P19: =AVERAGE(K19:O19) -> -0.0056216639 | Q19: =AVERAGE(L19:P19) -> -0.005431466 | R19: =AVERAGE(M19:Q19) -> -0.0054683289
B20: Tax Rate: | C20: =-C63/C61 -> 0.24679731 | D20: =-D63/D61 -> 0.24426883 | E20: =-E63/E61 -> 0.24527189 | F20: =-F63/F61 -> 0.24782969 | G20: =-G63/G61 -> 0.242997 | H20: =-H63/H61 -> 0.23000438 | I20: =-I63/I61 -> 0.25199295 | J20: =AVERAGE(G20:I20) -> 0.24166478 | K20: =-K63/K61 -> 0.24215879 | L20: =AVERAGE(C20:F20,K20) -> 0.2452653 | M20: =AVERAGE(K20:L20,D20:F20) -> 0.2449589 | N20: =AVERAGE(K20:M20,E20:F20) -> 0.24509691 | O20: =AVERAGE(K20:N20,F20) -> 0.24506192 | P20: =AVERAGE(K20:O20) -> 0.24450837 | Q20: =AVERAGE(L20:P20) -> 0.24497828 | R20: =AVERAGE(M20:Q20) -> 0.24492088
B21: NCI Net Income % Total: | C21: =C66/C65 -> 0.0025460959 | D21: =D66/D65 -> 0.0047261365 | E21: =E66/E65 -> 0.0020441609 | F21: =F66/F65 -> -0.00036723238 | G21: =G66/G65 -> -0.0032114339 | H21: =H66/H65 -> -0.0045805246 | I21: =I66/I65 -> -0.0055109939 | J21: =AVERAGE(G21:I21) -> -0.0044343175 | K21: =K66/K65 -> -0.0044389844 | L21: =AVERAGE(C21:F21,K21) -> 0.00090203528 | M21: =AVERAGE(K21:L21,D21:F21) -> 0.00057322317 | N21: =AVERAGE(K21:M21,E21:F21) -> -0.00025735949 | O21: =AVERAGE(K21:N21,F21) -> -0.00071766357 | P21: =AVERAGE(K21:O21) -> -0.00078774981 | Q21: =AVERAGE(L21:P21) -> -5.7502886e-05 | R21: =AVERAGE(M21:Q21) -> -0.00024941052
B23: Recessionary NWC Adj | L23: 0.024 | M23: 0.018 | N23: 0.006 | O23: 0.003 | P23: 0 | Q23: 0 | R23: 0
B24: NWC % Revenue: | C24: =C74/C49 -> 0.25876277 | D24: =D74/D49 -> 0.28188432 | E24: =E74/E49 -> 0.29790192 | F24: =F74/F49 -> 0.21149922 | G24: =G74/G49/4 -> 0.22572825 | H24: =H74/H49/4 -> 0.23255649 | I24: =I74/I49/4 -> 0.20670419 | J24: =AVERAGE(G24:I24) -> 0.22166298 | K24: =K74/K49 -> 0.22095922 | L24: ='3-Statement (Base)'!L21+L23 -> 0.24022922 | M24: ='3-Statement (Base)'!M21+M23 -> 0.23422922 | N24: ='3-Statement (Base)'!N21+N23 -> 0.22380589 | O24: ='3-Statement (Base)'!O21+O23 -> 0.21975477 | P24: ='3-Statement (Base)'!P21+P23 -> 0.21692996 | Q24: ='3-Statement (Base)'!Q21+Q23 -> 0.21716354 | R24: ='3-Statement (Base)'!R21+R23 -> 0.21694942
B25: Recessionary CapEx Adj | L25: -0.003 | M25: -0.002 | N25: -0.001 | O25: -0.001
B26: CapEx % Revenue: | C26: =-C106/C49 -> 0.014719651 | D26: =-D106/D49 -> 0.016571782 | E26: =-E106/E49 -> 0.016623721 | F26: =-F106/F49 -> 0.023069717 | G26: =-G106/G49 -> 0.019322431 | H26: =-H106/H49 -> 0.027102212 | I26: =-I106/I49 -> 0.030194517 | J26: =AVERAGE(G26:I26) -> 0.02553972 | K26: =-K106/K49 -> 0.025563026 | L26: ='3-Statement (Base)'!L22+L25 -> 0.016309579 | M26: ='3-Statement (Base)'!M22+M25 -> 0.018227565 | N26: ='3-Statement (Base)'!N22+N25 -> 0.019958722 | O26: ='3-Statement (Base)'!O22+O25 -> 0.020825722 | P26: ='3-Statement (Base)'!P22+P25 -> 0.021576923 | Q26: ='3-Statement (Base)'!Q22+Q25 -> 0.020779702 | R26: ='3-Statement (Base)'!R22+R25 -> 0.021073727
B27: D&A % Revenue: | C27: =C99/C49 -> 0.021638586 | D27: =D99/D49 -> 0.021227643 | E27: =E99/E49 -> 0.019062308 | F27: =F99/F49 -> 0.018738767 | G27: =G99/G49 -> 0.020736523 | H27: =H99/H49 -> 0.022764789 | I27: =I99/I49 -> 0.021085414 | J27: =AVERAGE(G27:I27) -> 0.021528909 | K27: =K99/K49 -> 0.021519939 | L27: =AVERAGE(C27:F27,K27) -> 0.020437448 | M27: =AVERAGE(K27:L27,D27:F27) -> 0.020197221 | N27: =AVERAGE(K27:M27,E27:F27) -> 0.019991137 | O27: =AVERAGE(K27:N27,F27) -> 0.020176902 | P27: =AVERAGE(K27:O27) -> 0.02046453 | Q27: =AVERAGE(L27:P27) -> 0.020253448 | R27: =AVERAGE(M27:Q27) -> 0.020216647
B28: Recessionary Other Adj | L28: -0.004 | M28: -0.004 | N28: -0.003 | O28: -0.002
B29: Other Items % Revenue: | C29: =C100/C49 -> 0.011421191 | D29: =D100/D49 -> 0.0039633402 | E29: =E100/E49 -> 0.0080557589 | F29: =F100/F49 -> 0.0090470064 | G29: =G100/G49 -> 0.005879646 | H29: =H100/H49 -> 0.0010830194 | I29: =I100/I49 -> -0.005415837 | J29: =AVERAGE(G29:I29) -> 0.00051560944 | K29: =K100/K49 -> 0.00047344292 | L29: ='3-Statement (Base)'!L25+L28 -> 0.00099204277 | M29: ='3-Statement (Base)'!M25+M28 -> 0.0018472361 | N29: ='3-Statement (Base)'!N25+N28 -> 0.0026600087 | O29: ='3-Statement (Base)'!O25+O28 -> 0.0029978089 | P29: ='3-Statement (Base)'!P25+P28 -> 0.0049906068 | Q29: ='3-Statement (Base)'!Q25+Q28 -> 0.0052975407 | R29: ='3-Statement (Base)'!R25+R28 -> 0.0053586402
B30: Acquisitions & Other % Revenue: | C30: =-C107/C48 -> 0.0007160759 | D30: =-D107/D48 -> 0.0067833736 | E30: =-E107/E48 -> 0.0089710076 | F30: =-F107/F48 -> 0.005033819 | G30: =-G107/G48 -> 0 | H30: =-H107/H48 -> 0.010550084 | I30: =-I107/I48 -> -9.1897687e-06 | J30: =AVERAGE(G30:I30) -> 0.0035136314 | K30: =K60/K49 -> -0.0049179226 | L30: =AVERAGE(C30:F30,K30) -> 0.0033172707 | M30: =AVERAGE(K30:L30,D30:F30) -> 0.0038375096 | N30: =AVERAGE(K30:M30,E30:F30) -> 0.0032483369 | O30: =AVERAGE(K30:N30,F30) -> 0.0021038027 | P30: =AVERAGE(K30:O30) -> 0.0015177995 | Q30: =AVERAGE(L30:P30) -> 0.0028049439 | R30: =AVERAGE(M30:Q30) -> 0.0027024785
B32: Dividends % Net Income: | C32: =-C113/C67 -> 0.6598164 | D32: =-D113/D67 -> 0.7640375 | E32: =-E113/E67 -> 0.49058263 | F32: =-F113/F67 -> 0.51523262 | G32: =-G113/G67 -> 0.68487505 | H32: =-H113/H67 -> 0.76321329 | I32: =-I113/I67 -> 0.65893484 | J32: =AVERAGE(G32:I32) -> 0.70234106 | K32: =-K113/K67 -> 0.70026602 | L32: ='3-Statement (Base)'!L27 -> 0.62720016 | M32: ='3-Statement (Base)'!M27 -> 0.62000322 | N32: ='3-Statement (Base)'!N27 -> 0.58974512 | O32: ='3-Statement (Base)'!O27 -> 0.60917567 | P32: ='3-Statement (Base)'!P27 -> 0.62803993 | Q32: ='3-Statement (Base)'!Q27 -> 0.61483282 | R32: ='3-Statement (Base)'!R27 -> 0.61235935
B33: Stock Repurchases % Net Income: | C33: =-C114/C67 -> 0.013645062 | D33: =-D114/D67 -> 0.32544173 | E33: =-E114/E67 -> 0.080189813 | F33: =-F114/F67 -> 0.27925454 | G33: =-G114/G67 -> 1.9163063 | H33: =-H114/H67 -> 0.27139664 | I33: =-I114/I67 -> 0.26070588 | J33: 0 | K33: =-K114/K67 -> 0.62907434 | L33: 0.25 | M33: 0.6 | N33: 0.5 | O33: 0.4 | P33: 0.35 | Q33: 0.35 | R33: 0.3 | S33: Set to maintain capital structure
B34: Other Items % Debt Issuances: | C34: =C116/(C112+C111) -> 0.10910804 | D34: =D116/(D112+D111) -> 0.20243173 | E34: =E116/(E112+E111) -> 5.6242536 | F34: =F116/(F112+F111) -> -0.10019784 | G34: =G116/(G112+G111) -> 0.087705615 | H34: =H116/(H112+H111) -> 0.14705469 | I34: =I116/(I112+I111) -> -0.00048888889 | J34: =AVERAGE(G34:I34) -> 0.078090472 | K34: =K116/(K112+K111) -> 0.12793826 | L34: =K34 -> 0.12793826 | M34: =L34 -> 0.12793826 | N34: =M34 -> 0.12793826 | O34: =N34 -> 0.12793826 | P34: =O34 -> 0.12793826 | Q34: =P34 -> 0.12793826 | R34: =Q34 -> 0.12793826
B36: Total Cash Flow Before Revolver | J36: =I73+J103+J108+SUM(J112:J116)+J119 -> 3769.1284 | K36: =J73+K103+K108+SUM(K112:K116)+K119 -> -62282.872 | L36: =K73+L103+L108+SUM(L112:L116)+L119 -> 25576.399 | M36: =L73+M103+M108+SUM(M112:M116)+M119 -> 25140.996 | N36: =M73+N103+N108+SUM(N112:N116)+N119 -> 36802.88 | O36: =N73+O103+O108+SUM(O112:O116)+O119 -> 20532.594 | P36: =O73+P103+P108+SUM(P112:P116)+P119 -> 24577.682 | Q36: =P73+Q103+Q108+SUM(Q112:Q116)+Q119 -> 9306.7277 | R36: =Q73+R103+R108+SUM(R112:R116)+R119 -> 18662.695
B37: Revolver Borrowing to Zero | J37: =-MIN(J36,I81) -> -3769.1284 | K37: =-MIN(K36,J81) -> 62282.872 | L37: =-MIN(L36,K81) -> -25576.399 | M37: =-MIN(M36,L81) -> -25140.996 | N37: =-MIN(N36,M81) -> -36802.88 | O37: =-MIN(O36,N81) -> -20532.594 | P37: =-MIN(P36,O81) -> -24577.682 | Q37: =-MIN(Q36,P81) -> -9306.7277 | R37: =-MIN(R36,Q81) -> -18662.695
B38: 25k Minimum Cash Balance | J38: 25000 | K38: 25000 | L38: 25000 | M38: 25000 | N38: 25000 | O38: 25000 | P38: 25000 | Q38: 25000 | R38: 25000 | S38: Estimate based on historicals
B39: Total Revolver Borrowing Needed | J39: =SUM(J37:J38) -> 21230.872 | K39: =SUM(K37:K38) -> 87282.872 | L39: =SUM(L37:L38) -> -576.39925 | M39: =SUM(M37:M38) -> -140.99577 | N39: =SUM(N37:N38) -> -11802.88 | O39: =SUM(O37:O38) -> 4467.4064 | P39: =SUM(P37:P38) -> 422.31766 | Q39: =SUM(Q37:Q38) -> 15693.272 | R39: =SUM(R37:R38) -> 6337.3053
